+ source /root/mugen/libs/locallibs/common_lib.sh
++ python3 --version
++ '[' 0 -eq 0 ']'
++ source /root/mugen/libs/locallibs/common_lib_python.sh
+ main
++ type -t post_test
+ '[' -n function ']'
+ trap post_test EXIT INT HUP TERM
+ rpm -qa
+ grep expect
++ type -t config_params
+ '[' -n '' ']'
++ type -t pre_test
+ '[' -n function ']'
+ pre_test
+ LOG_INFO 'Start to prepare the test environment.'
+ message='Start to prepare the test environment.'
+ python3 /root/mugen/libs/locallibs/mugen_log.py --level info --message 'Start to prepare the test environment.'
Thu Apr  6 22:59:56 2023 - INFO  - Start to prepare the test environment.
+ DNF_INSTALL 'freeradius freeradius-utils'
+ pkgs='freeradius freeradius-utils'
+ node=1
+ '[' -z '' ']'
+ tmpfile=
++ python3 /root/mugen/libs/locallibs/rpm_manage.py install --pkgs 'freeradius freeradius-utils' --node 1 --tempfile ''
+ tmpfile2='Error: Cannot open file /var/cache/dnf/mainline-2a8d8fb5c4598efe/packages/perl-Net-IP-1.26-1.oe2303.noarch.rpm: [Errno 2] No such file or directory: '\''/var/cache/dnf/mainline-2a8d8fb5c4598efe/packages/perl-Net-IP-1.26-1.oe2303.noarch.rpm'\''
TypeError: '\''NoneType'\'' object cannot be interpreted as an integer
FATAL ERROR: python callback ??? failed, aborting!'
+ '[' -z '' ']'
+ tmpfile='Error: Cannot open file /var/cache/dnf/mainline-2a8d8fb5c4598efe/packages/perl-Net-IP-1.26-1.oe2303.noarch.rpm: [Errno 2] No such file or directory: '\''/var/cache/dnf/mainline-2a8d8fb5c4598efe/packages/perl-Net-IP-1.26-1.oe2303.noarch.rpm'\''
TypeError: '\''NoneType'\'' object cannot be interpreted as an integer
FATAL ERROR: python callback ??? failed, aborting!'
+ ln -s /etc/raddb/mods-available/counter /etc/raddb/mods-enabled/counter
+ systemctl start radiusd
Job for radiusd.service canceled.
+ SLEEP_WAIT 2
+ wait_time=2
+ cmd=
+ mode=1
+ python3 /root/mugen/libs/locallibs/sleep_wait.py --time 2 --cmd '' --mode 1
+ LOG_INFO 'End to prepare the test environment.'
+ message='End to prepare the test environment.'
+ python3 /root/mugen/libs/locallibs/mugen_log.py --level info --message 'End to prepare the test environment.'
Thu Apr  6 23:06:45 2023 - INFO  - End to prepare the test environment.
++ type -t run_test
+ '[' -n function ']'
+ run_test
+ LOG_INFO 'Start to run test.'
+ message='Start to run test.'
+ python3 /root/mugen/libs/locallibs/mugen_log.py --level info --message 'Start to run test.'
Thu Apr  6 23:06:46 2023 - INFO  - Start to run test.
+ rad_counter --file /etc/raddb/db.daily --user test
Cannot open /etc/raddb/db.daily: No such file or directory
+ CHECK_RESULT 2 0 0 'rad_counter --user execution failed.'
+ actual_result=2
+ expect_result=0
+ mode=0
+ error_log='rad_counter --user execution failed.'
+ exit_mode=0
+ '[' -z 2 ']'
+ '[' 0 -eq 0 ']'
+ test 2x '!=' 0x
+ test -n 'rad_counter --user execution failed.'
+ LOG_ERROR 'rad_counter --user execution failed.'
+ message='rad_counter --user execution failed.'
+ python3 /root/mugen/libs/locallibs/mugen_log.py --level error --message 'rad_counter --user execution failed.'
Thu Apr  6 23:06:48 2023 - ERROR - rad_counter --user execution failed.
+ (( exec_result++ ))
+ LOG_ERROR 'oe_test_freeradius_freeradius-utils_rad_counter.sh line 36'
+ message='oe_test_freeradius_freeradius-utils_rad_counter.sh line 36'
+ python3 /root/mugen/libs/locallibs/mugen_log.py --level error --message 'oe_test_freeradius_freeradius-utils_rad_counter.sh line 36'
Thu Apr  6 23:06:49 2023 - ERROR - oe_test_freeradius_freeradius-utils_rad_counter.sh line 36
+ '[' 0 -eq 1 ']'
+ return 0
+ rad_counter --file /etc/raddb/db.daily --match '^te'
Cannot open /etc/raddb/db.daily: No such file or directory
+ CHECK_RESULT 2 0 0 'rad_counter --match execution failed.'
+ actual_result=2
+ expect_result=0
+ mode=0
+ error_log='rad_counter --match execution failed.'
+ exit_mode=0
+ '[' -z 2 ']'
+ '[' 0 -eq 0 ']'
+ test 2x '!=' 0x
+ test -n 'rad_counter --match execution failed.'
+ LOG_ERROR 'rad_counter --match execution failed.'
+ message='rad_counter --match execution failed.'
+ python3 /root/mugen/libs/locallibs/mugen_log.py --level error --message 'rad_counter --match execution failed.'
Thu Apr  6 23:06:50 2023 - ERROR - rad_counter --match execution failed.
+ (( exec_result++ ))
+ LOG_ERROR 'oe_test_freeradius_freeradius-utils_rad_counter.sh line 38'
+ message='oe_test_freeradius_freeradius-utils_rad_counter.sh line 38'
+ python3 /root/mugen/libs/locallibs/mugen_log.py --level error --message 'oe_test_freeradius_freeradius-utils_rad_counter.sh line 38'
Thu Apr  6 23:06:51 2023 - ERROR - oe_test_freeradius_freeradius-utils_rad_counter.sh line 38
+ '[' 0 -eq 1 ']'
+ return 0
+ rad_counter --file /etc/raddb/db.daily --reset 1
Cannot open /etc/raddb/db.daily: No such file or directory
+ CHECK_RESULT 2 0 0 'rad_counter --reset execution failed.'
+ actual_result=2
+ expect_result=0
+ mode=0
+ error_log='rad_counter --reset execution failed.'
+ exit_mode=0
+ '[' -z 2 ']'
+ '[' 0 -eq 0 ']'
+ test 2x '!=' 0x
+ test -n 'rad_counter --reset execution failed.'
+ LOG_ERROR 'rad_counter --reset execution failed.'
+ message='rad_counter --reset execution failed.'
+ python3 /root/mugen/libs/locallibs/mugen_log.py --level error --message 'rad_counter --reset execution failed.'
Thu Apr  6 23:06:52 2023 - ERROR - rad_counter --reset execution failed.
+ (( exec_result++ ))
+ LOG_ERROR 'oe_test_freeradius_freeradius-utils_rad_counter.sh line 40'
+ message='oe_test_freeradius_freeradius-utils_rad_counter.sh line 40'
+ python3 /root/mugen/libs/locallibs/mugen_log.py --level error --message 'oe_test_freeradius_freeradius-utils_rad_counter.sh line 40'
Thu Apr  6 23:06:53 2023 - ERROR - oe_test_freeradius_freeradius-utils_rad_counter.sh line 40
+ '[' 0 -eq 1 ']'
+ return 0
+ rad_counter --help
+ grep -i usage
Usage: rad_counter --file=<counter filename> [OPTION...]
+ CHECK_RESULT 0 0 0 'rad_counter --help execution failed.'
+ actual_result=0
+ expect_result=0
+ mode=0
+ error_log='rad_counter --help execution failed.'
+ exit_mode=0
+ '[' -z 0 ']'
+ '[' 0 -eq 0 ']'
+ test 0x '!=' 0x
+ return 0
+ rad_counter --file /etc/raddb/db.daily --hours 1
Cannot open /etc/raddb/db.daily: No such file or directory
+ CHECK_RESULT 2 0 0 'rad_counter --hours execution failed.'
+ actual_result=2
+ expect_result=0
+ mode=0
+ error_log='rad_counter --hours execution failed.'
+ exit_mode=0
+ '[' -z 2 ']'
+ '[' 0 -eq 0 ']'
+ test 2x '!=' 0x
+ test -n 'rad_counter --hours execution failed.'
+ LOG_ERROR 'rad_counter --hours execution failed.'
+ message='rad_counter --hours execution failed.'
+ python3 /root/mugen/libs/locallibs/mugen_log.py --level error --message 'rad_counter --hours execution failed.'
Thu Apr  6 23:06:56 2023 - ERROR - rad_counter --hours execution failed.
+ (( exec_result++ ))
+ LOG_ERROR 'oe_test_freeradius_freeradius-utils_rad_counter.sh line 44'
+ message='oe_test_freeradius_freeradius-utils_rad_counter.sh line 44'
+ python3 /root/mugen/libs/locallibs/mugen_log.py --level error --message 'oe_test_freeradius_freeradius-utils_rad_counter.sh line 44'
Thu Apr  6 23:06:56 2023 - ERROR - oe_test_freeradius_freeradius-utils_rad_counter.sh line 44
+ '[' 0 -eq 1 ']'
+ return 0
+ rad_counter --file /etc/raddb/db.daily --minutes 1
Cannot open /etc/raddb/db.daily: No such file or directory
+ CHECK_RESULT 2 0 0 'rad_counter --minutes execution failed.'
+ actual_result=2
+ expect_result=0
+ mode=0
+ error_log='rad_counter --minutes execution failed.'
+ exit_mode=0
+ '[' -z 2 ']'
+ '[' 0 -eq 0 ']'
+ test 2x '!=' 0x
+ test -n 'rad_counter --minutes execution failed.'
+ LOG_ERROR 'rad_counter --minutes execution failed.'
+ message='rad_counter --minutes execution failed.'
+ python3 /root/mugen/libs/locallibs/mugen_log.py --level error --message 'rad_counter --minutes execution failed.'
Thu Apr  6 23:06:58 2023 - ERROR - rad_counter --minutes execution failed.
+ (( exec_result++ ))
+ LOG_ERROR 'oe_test_freeradius_freeradius-utils_rad_counter.sh line 46'
+ message='oe_test_freeradius_freeradius-utils_rad_counter.sh line 46'
+ python3 /root/mugen/libs/locallibs/mugen_log.py --level error --message 'oe_test_freeradius_freeradius-utils_rad_counter.sh line 46'
Thu Apr  6 23:06:59 2023 - ERROR - oe_test_freeradius_freeradius-utils_rad_counter.sh line 46
+ '[' 0 -eq 1 ']'
+ return 0
+ rad_counter --file /etc/raddb/db.daily --seconds 1
Cannot open /etc/raddb/db.daily: No such file or directory
+ CHECK_RESULT 2 0 0 'rad_counter --seconds execution failed.'
+ actual_result=2
+ expect_result=0
+ mode=0
+ error_log='rad_counter --seconds execution failed.'
+ exit_mode=0
+ '[' -z 2 ']'
+ '[' 0 -eq 0 ']'
+ test 2x '!=' 0x
+ test -n 'rad_counter --seconds execution failed.'
+ LOG_ERROR 'rad_counter --seconds execution failed.'
+ message='rad_counter --seconds execution failed.'
+ python3 /root/mugen/libs/locallibs/mugen_log.py --level error --message 'rad_counter --seconds execution failed.'
Thu Apr  6 23:07:00 2023 - ERROR - rad_counter --seconds execution failed.
+ (( exec_result++ ))
+ LOG_ERROR 'oe_test_freeradius_freeradius-utils_rad_counter.sh line 48'
+ message='oe_test_freeradius_freeradius-utils_rad_counter.sh line 48'
+ python3 /root/mugen/libs/locallibs/mugen_log.py --level error --message 'oe_test_freeradius_freeradius-utils_rad_counter.sh line 48'
Thu Apr  6 23:07:01 2023 - ERROR - oe_test_freeradius_freeradius-utils_rad_counter.sh line 48
+ '[' 0 -eq 1 ']'
+ return 0
+ LOG_INFO 'End to run test.'
+ message='End to run test.'
+ python3 /root/mugen/libs/locallibs/mugen_log.py --level info --message 'End to run test.'
Thu Apr  6 23:07:02 2023 - INFO  - End to run test.
+ CASE_RESULT 0
+ case_re=0
+ test -z 6
+ test 6 -gt 0
+ LOG_ERROR 'failed to execute the case.'
+ message='failed to execute the case.'
+ python3 /root/mugen/libs/locallibs/mugen_log.py --level error --message 'failed to execute the case.'
Thu Apr  6 23:07:03 2023 - ERROR - failed to execute the case.
+ exit 6
+ post_test
+ LOG_INFO 'Start to restore the test environment.'
+ message='Start to restore the test environment.'
+ python3 /root/mugen/libs/locallibs/mugen_log.py --level info --message 'Start to restore the test environment.'
Thu Apr  6 23:07:04 2023 - INFO  - Start to restore the test environment.
+ systemctl stop radiusd
+ DNF_REMOVE
+ node=1
+ pkg_list=
+ mode=0
+ [[ -z Error: Cannot open file /var/cache/dnf/mainline-2a8d8fb5c4598efe/packages/perl-Net-IP-1.26-1.oe2303.noarch.rpm: [Errno 2] No such file or directory: '/var/cache/dnf/mainline-2a8d8fb5c4598efe/packages/perl-Net-IP-1.26-1.oe2303.noarch.rpm'
TypeError: 'NoneType' object cannot be interpreted as an integer
FATAL ERROR: python callback ??? failed, aborting! ]]
+ '[' 0 -ne 0 ']'
+ '[' 1 == 0 ']'
+ python3 /root/mugen/libs/locallibs/rpm_manage.py remove --node 1 --pkgs '' --tempfile 'Error: Cannot open file /var/cache/dnf/mainline-2a8d8fb5c4598efe/packages/perl-Net-IP-1.26-1.oe2303.noarch.rpm: [Errno 2] No such file or directory: '\''/var/cache/dnf/mainline-2a8d8fb5c4598efe/packages/perl-Net-IP-1.26-1.oe2303.noarch.rpm'\''
TypeError: '\''NoneType'\'' object cannot be interpreted as an integer
FATAL ERROR: python callback ??? failed, aborting!'
Traceback (most recent call last):
  File "/root/mugen/libs/locallibs/rpm_manage.py", line 181, in <module>
    exitcode = rpm_remove(args.node, args.pkgs, args.tempfile)
  File "/root/mugen/libs/locallibs/rpm_manage.py", line 152, in rpm_remove
    with open(tmpfile, "r") as f:
FileNotFoundError: [Errno 2] No such file or directory: "Error: Cannot open file /var/cache/dnf/mainline-2a8d8fb5c4598efe/packages/perl-Net-IP-1.26-1.oe2303.noarch.rpm: [Errno 2] No such file or directory: '/var/cache/dnf/mainline-2a8d8fb5c4598efe/packages/perl-Net-IP-1.26-1.oe2303.noarch.rpm'\nTypeError: 'NoneType' object cannot be interpreted as an integer\nFATAL ERROR: python callback ??? failed, aborting!"
+ '[' 0 -ne 0 ']'
+ rm -rf /etc/raddb
+ rm -rf /var/log/radius
+ LOG_INFO 'End to restore the test environment.'
+ message='End to restore the test environment.'
+ python3 /root/mugen/libs/locallibs/mugen_log.py --level info --message 'End to restore the test environment.'
Thu Apr  6 23:07:10 2023 - INFO  - End to restore the test environment.
